--- Logging error in Loguru Handler #0 ---
Record was: {'elapsed': datetime.timedelta(seconds=159, microseconds=89577), 'exception': None, 'extra': {}, 'file': (name='runner.py', path='D:\\python3.8\\projects\\Django\\djenv\\lib\\site-packages\\httprunner\\runner.py'), 'function': 'test_start', 'level': (name='INFO', no=20, icon='ℹ️'), 'line': 450, 'message': 'Start to run testcase: vivo手机发布会, TestCase ID: 1a52fd7b-6089-4b78-bd57-b82e0013ff54', 'module': 'runner', 'name': 'httprunner.runner', 'process': (id=2320, name='MainProcess'), 'thread': (id=10252, name='Thread-1'), 'time': datetime(2022, 10, 10, 0, 8, 55, 428921, tzinfo=datetime.timezone(datetime.timedelta(seconds=28800), '中国标准时间'))}
Traceback (most recent call last):
  File "D:\python3.8\projects\Django\djenv\lib\site-packages\loguru\_handler.py", line 177, in emit
    self._sink.write(str_record)
  File "D:\python3.8\projects\Django\djenv\lib\site-packages\loguru\_simple_sinks.py", line 26, in write
    self._stream.write(message)
  File "D:\python3.8\projects\Django\djenv\lib\site-packages\colorama\ansitowin32.py", line 47, in write
    self.__convertor.write(text)
  File "D:\python3.8\projects\Django\djenv\lib\site-packages\colorama\ansitowin32.py", line 170, in write
    self.write_and_convert(text)
  File "D:\python3.8\projects\Django\djenv\lib\site-packages\colorama\ansitowin32.py", line 195, in write_and_convert
    self.write_plain_text(text, cursor, start)
  File "D:\python3.8\projects\Django\djenv\lib\site-packages\colorama\ansitowin32.py", line 203, in write_plain_text
    self.wrapped.write(text[start:end])
  File "D:\python3.8\projects\Django\djenv\lib\site-packages\colorama\ansitowin32.py", line 47, in write
    self.__convertor.write(text)
  File "D:\python3.8\projects\Django\djenv\lib\site-packages\colorama\ansitowin32.py", line 170, in write
    self.write_and_convert(text)
  File "D:\python3.8\projects\Django\djenv\lib\site-packages\colorama\ansitowin32.py", line 198, in write_and_convert
    self.write_plain_text(text, cursor, len(text))
  File "D:\python3.8\projects\Django\djenv\lib\site-packages\colorama\ansitowin32.py", line 204, in write_plain_text
    self.wrapped.flush()
OSError: [WinError 6] 句柄无效。
--- End of logging error ---
--- Logging error in Loguru Handler #0 ---
Record was: {'elapsed': datetime.timedelta(seconds=159, microseconds=116504), 'exception': None, 'extra': {}, 'file': (name='runner.py', path='D:\\python3.8\\projects\\Django\\djenv\\lib\\site-packages\\httprunner\\runner.py'), 'function': '__run_step', 'level': (name='INFO', no=20, icon='ℹ️'), 'line': 292, 'message': 'run step begin: step_name >>>>>>', 'module': 'runner', 'name': 'httprunner.runner', 'process': (id=2320, name='MainProcess'), 'thread': (id=10252, name='Thread-1'), 'time': datetime(2022, 10, 10, 0, 8, 55, 455848, tzinfo=datetime.timezone(datetime.timedelta(seconds=28800), '中国标准时间'))}
Traceback (most recent call last):
  File "D:\python3.8\projects\Django\djenv\lib\site-packages\loguru\_handler.py", line 177, in emit
    self._sink.write(str_record)
  File "D:\python3.8\projects\Django\djenv\lib\site-packages\loguru\_simple_sinks.py", line 26, in write
    self._stream.write(message)
  File "D:\python3.8\projects\Django\djenv\lib\site-packages\colorama\ansitowin32.py", line 47, in write
    self.__convertor.write(text)
  File "D:\python3.8\projects\Django\djenv\lib\site-packages\colorama\ansitowin32.py", line 170, in write
    self.write_and_convert(text)
  File "D:\python3.8\projects\Django\djenv\lib\site-packages\colorama\ansitowin32.py", line 195, in write_and_convert
    self.write_plain_text(text, cursor, start)
  File "D:\python3.8\projects\Django\djenv\lib\site-packages\colorama\ansitowin32.py", line 203, in write_plain_text
    self.wrapped.write(text[start:end])
  File "D:\python3.8\projects\Django\djenv\lib\site-packages\colorama\ansitowin32.py", line 47, in write
    self.__convertor.write(text)
  File "D:\python3.8\projects\Django\djenv\lib\site-packages\colorama\ansitowin32.py", line 170, in write
    self.write_and_convert(text)
  File "D:\python3.8\projects\Django\djenv\lib\site-packages\colorama\ansitowin32.py", line 198, in write_and_convert
    self.write_plain_text(text, cursor, len(text))
  File "D:\python3.8\projects\Django\djenv\lib\site-packages\colorama\ansitowin32.py", line 204, in write_plain_text
    self.wrapped.flush()
OSError: [WinError 6] 句柄无效。
--- End of logging error ---
--- Logging error ---
Traceback (most recent call last):
  File "D:\python3.8\lib\logging\__init__.py", line 1084, in emit
    stream.write(msg + self.terminator)
  File "D:\python3.8\projects\Django\djenv\lib\site-packages\colorama\ansitowin32.py", line 47, in write
    self.__convertor.write(text)
  File "D:\python3.8\projects\Django\djenv\lib\site-packages\colorama\ansitowin32.py", line 170, in write
    self.write_and_convert(text)
  File "D:\python3.8\projects\Django\djenv\lib\site-packages\colorama\ansitowin32.py", line 195, in write_and_convert
    self.write_plain_text(text, cursor, start)
  File "D:\python3.8\projects\Django\djenv\lib\site-packages\colorama\ansitowin32.py", line 204, in write_plain_text
    self.wrapped.flush()
OSError: [WinError 6] 句柄无效。
Call stack:
  File "D:\python3.8\lib\threading.py", line 890, in _bootstrap
    self._bootstrap_inner()
  File "D:\python3.8\lib\threading.py", line 932, in _bootstrap_inner
    self.run()
  File "D:\python3.8\projects\Django\djenv\lib\site-packages\sentry_sdk\integrations\threading.py", line 67, in run
    return old_run_func(self, *a, **kw)
  File "D:\python3.8\lib\threading.py", line 870, in run
    self._target(*self._args, **self._kwargs)
  File "D:\python3.8\lib\socketserver.py", line 650, in process_request_thread
    self.finish_request(request, client_address)
  File "D:\python3.8\lib\socketserver.py", line 360, in finish_request
    self.RequestHandlerClass(request, client_address, self)
  File "D:\python3.8\lib\socketserver.py", line 720, in __init__
    self.handle()
  File "D:\python3.8\projects\Django\djenv\lib\site-packages\django\core\servers\basehttp.py", line 176, in handle
    self.handle_one_request()
  File "D:\python3.8\projects\Django\djenv\lib\site-packages\django\core\servers\basehttp.py", line 201, in handle_one_request
    handler.run(self.server.get_app())
  File "D:\python3.8\lib\wsgiref\handlers.py", line 138, in run
    self.finish_response()
  File "D:\python3.8\lib\wsgiref\handlers.py", line 196, in finish_response
    self.close()
  File "D:\python3.8\projects\Django\djenv\lib\site-packages\django\core\servers\basehttp.py", line 118, in close
    super().close()
  File "D:\python3.8\lib\wsgiref\simple_server.py", line 34, in close
    self.request_handler.log_request(
  File "D:\python3.8\lib\http\server.py", line 544, in log_request
    self.log_message('"%s" %s %s',
  File "D:\python3.8\projects\Django\djenv\lib\site-packages\django\core\servers\basehttp.py", line 161, in log_message
    level(format, *args, extra=extra)
  File "D:\python3.8\lib\logging\__init__.py", line 1434, in info
    self._log(INFO, msg, args, **kwargs)
  File "D:\python3.8\lib\logging\__init__.py", line 1577, in _log
    self.handle(record)
  File "D:\python3.8\lib\logging\__init__.py", line 1587, in handle
    self.callHandlers(record)
  File "D:\python3.8\projects\Django\djenv\lib\site-packages\sentry_sdk\integrations\logging.py", line 83, in sentry_patched_callhandlers
    return old_callhandlers(self, record)
Message: '\x1b[m"%s" %s %s\x1b[0m'
Arguments: ('GET /api/current_user/ HTTP/1.1', '200', '249')
--- Logging error ---
Traceback (most recent call last):
  File "D:\python3.8\lib\logging\__init__.py", line 1084, in emit
    stream.write(msg + self.terminator)
  File "D:\python3.8\projects\Django\djenv\lib\site-packages\colorama\ansitowin32.py", line 47, in write
    self.__convertor.write(text)
  File "D:\python3.8\projects\Django\djenv\lib\site-packages\colorama\ansitowin32.py", line 170, in write
    self.write_and_convert(text)
  File "D:\python3.8\projects\Django\djenv\lib\site-packages\colorama\ansitowin32.py", line 195, in write_and_convert
    self.write_plain_text(text, cursor, start)
  File "D:\python3.8\projects\Django\djenv\lib\site-packages\colorama\ansitowin32.py", line 204, in write_plain_text
    self.wrapped.flush()
OSError: [WinError 6] 句柄无效。
Call stack:
  File "D:\python3.8\lib\threading.py", line 890, in _bootstrap
    self._bootstrap_inner()
  File "D:\python3.8\lib\threading.py", line 932, in _bootstrap_inner
    self.run()
  File "D:\python3.8\projects\Django\djenv\lib\site-packages\sentry_sdk\integrations\threading.py", line 67, in run
    return old_run_func(self, *a, **kw)
  File "D:\python3.8\lib\threading.py", line 870, in run
    self._target(*self._args, **self._kwargs)
  File "D:\python3.8\lib\socketserver.py", line 650, in process_request_thread
    self.finish_request(request, client_address)
  File "D:\python3.8\lib\socketserver.py", line 360, in finish_request
    self.RequestHandlerClass(request, client_address, self)
  File "D:\python3.8\lib\socketserver.py", line 720, in __init__
    self.handle()
  File "D:\python3.8\projects\Django\djenv\lib\site-packages\django\core\servers\basehttp.py", line 178, in handle
    self.handle_one_request()
  File "D:\python3.8\projects\Django\djenv\lib\site-packages\django\core\servers\basehttp.py", line 201, in handle_one_request
    handler.run(self.server.get_app())
  File "D:\python3.8\lib\wsgiref\handlers.py", line 138, in run
    self.finish_response()
  File "D:\python3.8\lib\wsgiref\handlers.py", line 196, in finish_response
    self.close()
  File "D:\python3.8\projects\Django\djenv\lib\site-packages\django\core\servers\basehttp.py", line 118, in close
    super().close()
  File "D:\python3.8\lib\wsgiref\simple_server.py", line 34, in close
    self.request_handler.log_request(
  File "D:\python3.8\lib\http\server.py", line 544, in log_request
    self.log_message('"%s" %s %s',
  File "D:\python3.8\projects\Django\djenv\lib\site-packages\django\core\servers\basehttp.py", line 161, in log_message
    level(format, *args, extra=extra)
  File "D:\python3.8\lib\logging\__init__.py", line 1434, in info
    self._log(INFO, msg, args, **kwargs)
  File "D:\python3.8\lib\logging\__init__.py", line 1577, in _log
    self.handle(record)
  File "D:\python3.8\lib\logging\__init__.py", line 1587, in handle
    self.callHandlers(record)
  File "D:\python3.8\projects\Django\djenv\lib\site-packages\sentry_sdk\integrations\logging.py", line 83, in sentry_patched_callhandlers
    return old_callhandlers(self, record)
Message: '\x1b[m"%s" %s %s\x1b[0m'
Arguments: ('GET /api/reports/?page_size=5&page_index=1 HTTP/1.1', '200', '13924')
--- Logging error in Loguru Handler #0 ---
Record was: {'elapsed': datetime.timedelta(seconds=163, microseconds=214999), 'exception': None, 'extra': {}, 'file': (name='client.py', path='D:\\python3.8\\projects\\Django\\djenv\\lib\\site-packages\\httprunner\\client.py'), 'function': 'request', 'level': (name='WARNING', no=30, icon='⚠️'), 'line': 188, 'message': "failed to get client address info: 'NoneType' object has no attribute 'connection'", 'module': 'client', 'name': 'httprunner.client', 'process': (id=2320, name='MainProcess'), 'thread': (id=10252, name='Thread-1'), 'time': datetime(2022, 10, 10, 0, 8, 59, 554343, tzinfo=datetime.timezone(datetime.timedelta(seconds=28800), '中国标准时间'))}
Traceback (most recent call last):
  File "D:\python3.8\projects\Django\djenv\lib\site-packages\httprunner\client.py", line 183, in request
    client_ip, client_port = response.raw.connection.sock.getsockname()
AttributeError: 'NoneType' object has no attribute 'connection'

During handling of the above exception, another exception occurred:

Traceback (most recent call last):
  File "D:\python3.8\projects\Django\djenv\lib\site-packages\loguru\_handler.py", line 177, in emit
    self._sink.write(str_record)
  File "D:\python3.8\projects\Django\djenv\lib\site-packages\loguru\_simple_sinks.py", line 26, in write
    self._stream.write(message)
  File "D:\python3.8\projects\Django\djenv\lib\site-packages\colorama\ansitowin32.py", line 47, in write
    self.__convertor.write(text)
  File "D:\python3.8\projects\Django\djenv\lib\site-packages\colorama\ansitowin32.py", line 170, in write
    self.write_and_convert(text)
  File "D:\python3.8\projects\Django\djenv\lib\site-packages\colorama\ansitowin32.py", line 195, in write_and_convert
    self.write_plain_text(text, cursor, start)
  File "D:\python3.8\projects\Django\djenv\lib\site-packages\colorama\ansitowin32.py", line 203, in write_plain_text
    self.wrapped.write(text[start:end])
  File "D:\python3.8\projects\Django\djenv\lib\site-packages\colorama\ansitowin32.py", line 47, in write
    self.__convertor.write(text)
  File "D:\python3.8\projects\Django\djenv\lib\site-packages\colorama\ansitowin32.py", line 170, in write
    self.write_and_convert(text)
  File "D:\python3.8\projects\Django\djenv\lib\site-packages\colorama\ansitowin32.py", line 198, in write_and_convert
    self.write_plain_text(text, cursor, len(text))
  File "D:\python3.8\projects\Django\djenv\lib\site-packages\colorama\ansitowin32.py", line 204, in write_plain_text
    self.wrapped.flush()
OSError: [WinError 6] 句柄无效。
--- End of logging error ---
--- Logging error in Loguru Handler #0 ---
Record was: {'elapsed': datetime.timedelta(seconds=163, microseconds=257885), 'exception': None, 'extra': {}, 'file': (name='client.py', path='D:\\python3.8\\projects\\Django\\djenv\\lib\\site-packages\\httprunner\\client.py'), 'function': 'request', 'level': (name='WARNING', no=30, icon='⚠️'), 'line': 196, 'message': "failed to get server address info: 'NoneType' object has no attribute 'connection'", 'module': 'client', 'name': 'httprunner.client', 'process': (id=2320, name='MainProcess'), 'thread': (id=10252, name='Thread-1'), 'time': datetime(2022, 10, 10, 0, 8, 59, 597229, tzinfo=datetime.timezone(datetime.timedelta(seconds=28800), '中国标准时间'))}
Traceback (most recent call last):
  File "D:\python3.8\projects\Django\djenv\lib\site-packages\httprunner\client.py", line 191, in request
    server_ip, server_port = response.raw.connection.sock.getpeername()
AttributeError: 'NoneType' object has no attribute 'connection'

During handling of the above exception, another exception occurred:

Traceback (most recent call last):
  File "D:\python3.8\projects\Django\djenv\lib\site-packages\loguru\_handler.py", line 177, in emit
    self._sink.write(str_record)
  File "D:\python3.8\projects\Django\djenv\lib\site-packages\loguru\_simple_sinks.py", line 26, in write
    self._stream.write(message)
  File "D:\python3.8\projects\Django\djenv\lib\site-packages\colorama\ansitowin32.py", line 47, in write
    self.__convertor.write(text)
  File "D:\python3.8\projects\Django\djenv\lib\site-packages\colorama\ansitowin32.py", line 170, in write
    self.write_and_convert(text)
  File "D:\python3.8\projects\Django\djenv\lib\site-packages\colorama\ansitowin32.py", line 195, in write_and_convert
    self.write_plain_text(text, cursor, start)
  File "D:\python3.8\projects\Django\djenv\lib\site-packages\colorama\ansitowin32.py", line 203, in write_plain_text
    self.wrapped.write(text[start:end])
  File "D:\python3.8\projects\Django\djenv\lib\site-packages\colorama\ansitowin32.py", line 47, in write
    self.__convertor.write(text)
  File "D:\python3.8\projects\Django\djenv\lib\site-packages\colorama\ansitowin32.py", line 170, in write
    self.write_and_convert(text)
  File "D:\python3.8\projects\Django\djenv\lib\site-packages\colorama\ansitowin32.py", line 198, in write_and_convert
    self.write_plain_text(text, cursor, len(text))
  File "D:\python3.8\projects\Django\djenv\lib\site-packages\colorama\ansitowin32.py", line 204, in write_plain_text
    self.wrapped.flush()
OSError: [WinError 6] 句柄无效。
--- End of logging error ---
--- Logging error in Loguru Handler #0 ---
Record was: {'elapsed': datetime.timedelta(seconds=163, microseconds=258888), 'exception': None, 'extra': {}, 'file': (name='client.py', path='D:\\python3.8\\projects\\Django\\djenv\\lib\\site-packages\\httprunner\\client.py'), 'function': 'log_print', 'level': (name='DEBUG', no=10, icon='🐞'), 'line': 40, 'message': '\n================== request details ==================\nmethod   : GET\nurl      : https://localhost/demo/path\nheaders  : {}\ncookies  : {}\nbody     : None\n', 'module': 'client', 'name': 'httprunner.client', 'process': (id=2320, name='MainProcess'), 'thread': (id=10252, name='Thread-1'), 'time': datetime(2022, 10, 10, 0, 8, 59, 598232, tzinfo=datetime.timezone(datetime.timedelta(seconds=28800), '中国标准时间'))}
Traceback (most recent call last):
  File "D:\python3.8\projects\Django\djenv\lib\site-packages\loguru\_handler.py", line 177, in emit
    self._sink.write(str_record)
  File "D:\python3.8\projects\Django\djenv\lib\site-packages\loguru\_simple_sinks.py", line 26, in write
    self._stream.write(message)
  File "D:\python3.8\projects\Django\djenv\lib\site-packages\colorama\ansitowin32.py", line 47, in write
    self.__convertor.write(text)
  File "D:\python3.8\projects\Django\djenv\lib\site-packages\colorama\ansitowin32.py", line 170, in write
    self.write_and_convert(text)
  File "D:\python3.8\projects\Django\djenv\lib\site-packages\colorama\ansitowin32.py", line 195, in write_and_convert
    self.write_plain_text(text, cursor, start)
  File "D:\python3.8\projects\Django\djenv\lib\site-packages\colorama\ansitowin32.py", line 203, in write_plain_text
    self.wrapped.write(text[start:end])
  File "D:\python3.8\projects\Django\djenv\lib\site-packages\colorama\ansitowin32.py", line 47, in write
    self.__convertor.write(text)
  File "D:\python3.8\projects\Django\djenv\lib\site-packages\colorama\ansitowin32.py", line 170, in write
    self.write_and_convert(text)
  File "D:\python3.8\projects\Django\djenv\lib\site-packages\colorama\ansitowin32.py", line 198, in write_and_convert
    self.write_plain_text(text, cursor, len(text))
  File "D:\python3.8\projects\Django\djenv\lib\site-packages\colorama\ansitowin32.py", line 204, in write_plain_text
    self.wrapped.flush()
OSError: [WinError 6] 句柄无效。
--- End of logging error ---
--- Logging error in Loguru Handler #0 ---
Record was: {'elapsed': datetime.timedelta(seconds=163, microseconds=260878), 'exception': None, 'extra': {}, 'file': (name='client.py', path='D:\\python3.8\\projects\\Django\\djenv\\lib\\site-packages\\httprunner\\client.py'), 'function': 'log_print', 'level': (name='DEBUG', no=10, icon='🐞'), 'line': 40, 'message': '\n================== response details ==================\nstatus_code : 0\nheaders  : {}\ncookies  : {}\nencoding : None\ncontent_type : \nbody     : \n', 'module': 'client', 'name': 'httprunner.client', 'process': (id=2320, name='MainProcess'), 'thread': (id=10252, name='Thread-1'), 'time': datetime(2022, 10, 10, 0, 8, 59, 600222, tzinfo=datetime.timezone(datetime.timedelta(seconds=28800), '中国标准时间'))}
Traceback (most recent call last):
  File "D:\python3.8\projects\Django\djenv\lib\site-packages\loguru\_handler.py", line 177, in emit
    self._sink.write(str_record)
  File "D:\python3.8\projects\Django\djenv\lib\site-packages\loguru\_simple_sinks.py", line 26, in write
    self._stream.write(message)
  File "D:\python3.8\projects\Django\djenv\lib\site-packages\colorama\ansitowin32.py", line 47, in write
    self.__convertor.write(text)
  File "D:\python3.8\projects\Django\djenv\lib\site-packages\colorama\ansitowin32.py", line 170, in write
    self.write_and_convert(text)
  File "D:\python3.8\projects\Django\djenv\lib\site-packages\colorama\ansitowin32.py", line 195, in write_and_convert
    self.write_plain_text(text, cursor, start)
  File "D:\python3.8\projects\Django\djenv\lib\site-packages\colorama\ansitowin32.py", line 203, in write_plain_text
    self.wrapped.write(text[start:end])
  File "D:\python3.8\projects\Django\djenv\lib\site-packages\colorama\ansitowin32.py", line 47, in write
    self.__convertor.write(text)
  File "D:\python3.8\projects\Django\djenv\lib\site-packages\colorama\ansitowin32.py", line 170, in write
    self.write_and_convert(text)
  File "D:\python3.8\projects\Django\djenv\lib\site-packages\colorama\ansitowin32.py", line 198, in write_and_convert
    self.write_plain_text(text, cursor, len(text))
  File "D:\python3.8\projects\Django\djenv\lib\site-packages\colorama\ansitowin32.py", line 204, in write_plain_text
    self.wrapped.flush()
OSError: [WinError 6] 句柄无效。
--- End of logging error ---
--- Logging error in Loguru Handler #0 ---
Record was: {'elapsed': datetime.timedelta(seconds=163, microseconds=262875), 'exception': None, 'extra': {}, 'file': (name='client.py', path='D:\\python3.8\\projects\\Django\\djenv\\lib\\site-packages\\httprunner\\client.py'), 'function': 'request', 'level': (name='ERROR', no=40, icon='❌'), 'line': 215, 'message': "HTTPSConnectionPool(host='localhost', port=443): Max retries exceeded with url: /demo/path (Caused by NewConnectionError('<urllib3.connection.HTTPSConnection object at 0x000001EFA58B2250>: Failed to establish a new connection: [WinError 10061] 由于目标计算机积极拒绝，无法连接。'))", 'module': 'client', 'name': 'httprunner.client', 'process': (id=2320, name='MainProcess'), 'thread': (id=10252, name='Thread-1'), 'time': datetime(2022, 10, 10, 0, 8, 59, 602219, tzinfo=datetime.timezone(datetime.timedelta(seconds=28800), '中国标准时间'))}
Traceback (most recent call last):
  File "D:\python3.8\projects\Django\djenv\lib\site-packages\urllib3\connection.py", line 174, in _new_conn
    conn = connection.create_connection(
  File "D:\python3.8\projects\Django\djenv\lib\site-packages\urllib3\util\connection.py", line 95, in create_connection
    raise err
  File "D:\python3.8\projects\Django\djenv\lib\site-packages\urllib3\util\connection.py", line 85, in create_connection
    sock.connect(sa)
ConnectionRefusedError: [WinError 10061] 由于目标计算机积极拒绝，无法连接。

During handling of the above exception, another exception occurred:

Traceback (most recent call last):
  File "D:\python3.8\projects\Django\djenv\lib\site-packages\urllib3\connectionpool.py", line 703, in urlopen
    httplib_response = self._make_request(
  File "D:\python3.8\projects\Django\djenv\lib\site-packages\urllib3\connectionpool.py", line 386, in _make_request
    self._validate_conn(conn)
  File "D:\python3.8\projects\Django\djenv\lib\site-packages\urllib3\connectionpool.py", line 1042, in _validate_conn
    conn.connect()
  File "D:\python3.8\projects\Django\djenv\lib\site-packages\urllib3\connection.py", line 358, in connect
    self.sock = conn = self._new_conn()
  File "D:\python3.8\projects\Django\djenv\lib\site-packages\urllib3\connection.py", line 186, in _new_conn
    raise NewConnectionError(
urllib3.exceptions.NewConnectionError: <urllib3.connection.HTTPSConnection object at 0x000001EFA58B2250>: Failed to establish a new connection: [WinError 10061] 由于目标计算机积极拒绝，无法连接。

During handling of the above exception, another exception occurred:

Traceback (most recent call last):
  File "D:\python3.8\projects\Django\djenv\lib\site-packages\requests\adapters.py", line 489, in send
    resp = conn.urlopen(
  File "D:\python3.8\projects\Django\djenv\lib\site-packages\urllib3\connectionpool.py", line 787, in urlopen
    retries = retries.increment(
  File "D:\python3.8\projects\Django\djenv\lib\site-packages\urllib3\util\retry.py", line 592, in increment
    raise MaxRetryError(_pool, url, error or ResponseError(cause))
urllib3.exceptions.MaxRetryError: HTTPSConnectionPool(host='localhost', port=443): Max retries exceeded with url: /demo/path (Caused by NewConnectionError('<urllib3.connection.HTTPSConnection object at 0x000001EFA58B2250>: Failed to establish a new connection: [WinError 10061] 由于目标计算机积极拒绝，无法连接。'))

During handling of the above exception, another exception occurred:

Traceback (most recent call last):
  File "D:\python3.8\projects\Django\djenv\lib\site-packages\httprunner\client.py", line 213, in request
    response.raise_for_status()
  File "D:\python3.8\projects\Django\djenv\lib\site-packages\httprunner\client.py", line 25, in raise_for_status
    raise self.error
  File "D:\python3.8\projects\Django\djenv\lib\site-packages\httprunner\client.py", line 231, in _send_request_safe_mode
    return requests.Session.request(self, method, url, **kwargs)
  File "D:\python3.8\projects\Django\djenv\lib\site-packages\requests\sessions.py", line 587, in request
    resp = self.send(prep, **send_kwargs)
  File "D:\python3.8\projects\Django\djenv\lib\site-packages\requests\sessions.py", line 701, in send
    r = adapter.send(request, **kwargs)
  File "D:\python3.8\projects\Django\djenv\lib\site-packages\requests\adapters.py", line 565, in send
    raise ConnectionError(e, request=request)
requests.exceptions.ConnectionError: HTTPSConnectionPool(host='localhost', port=443): Max retries exceeded with url: /demo/path (Caused by NewConnectionError('<urllib3.connection.HTTPSConnection object at 0x000001EFA58B2250>: Failed to establish a new connection: [WinError 10061] 由于目标计算机积极拒绝，无法连接。'))

During handling of the above exception, another exception occurred:

Traceback (most recent call last):
  File "D:\python3.8\projects\Django\djenv\lib\site-packages\loguru\_handler.py", line 177, in emit
    self._sink.write(str_record)
  File "D:\python3.8\projects\Django\djenv\lib\site-packages\loguru\_simple_sinks.py", line 26, in write
    self._stream.write(message)
  File "D:\python3.8\projects\Django\djenv\lib\site-packages\colorama\ansitowin32.py", line 47, in write
    self.__convertor.write(text)
  File "D:\python3.8\projects\Django\djenv\lib\site-packages\colorama\ansitowin32.py", line 170, in write
    self.write_and_convert(text)
  File "D:\python3.8\projects\Django\djenv\lib\site-packages\colorama\ansitowin32.py", line 195, in write_and_convert
    self.write_plain_text(text, cursor, start)
  File "D:\python3.8\projects\Django\djenv\lib\site-packages\colorama\ansitowin32.py", line 203, in write_plain_text
    self.wrapped.write(text[start:end])
  File "D:\python3.8\projects\Django\djenv\lib\site-packages\colorama\ansitowin32.py", line 47, in write
    self.__convertor.write(text)
  File "D:\python3.8\projects\Django\djenv\lib\site-packages\colorama\ansitowin32.py", line 170, in write
    self.write_and_convert(text)
  File "D:\python3.8\projects\Django\djenv\lib\site-packages\colorama\ansitowin32.py", line 198, in write_and_convert
    self.write_plain_text(text, cursor, len(text))
  File "D:\python3.8\projects\Django\djenv\lib\site-packages\colorama\ansitowin32.py", line 204, in write_plain_text
    self.wrapped.flush()
OSError: [WinError 6] 句柄无效。
--- End of logging error ---
--- Logging error in Loguru Handler #0 ---
Record was: {'elapsed': datetime.timedelta(seconds=163, microseconds=344685), 'exception': None, 'extra': {}, 'file': (name='runner.py', path='D:\\python3.8\\projects\\Django\\djenv\\lib\\site-packages\\httprunner\\runner.py'), 'function': '__run_step', 'level': (name='INFO', no=20, icon='ℹ️'), 'line': 304, 'message': 'run step end: step_name <<<<<<\n', 'module': 'runner', 'name': 'httprunner.runner', 'process': (id=2320, name='MainProcess'), 'thread': (id=10252, name='Thread-1'), 'time': datetime(2022, 10, 10, 0, 8, 59, 684029, tzinfo=datetime.timezone(datetime.timedelta(seconds=28800), '中国标准时间'))}
Traceback (most recent call last):
  File "D:\python3.8\projects\Django\djenv\lib\site-packages\loguru\_handler.py", line 177, in emit
    self._sink.write(str_record)
  File "D:\python3.8\projects\Django\djenv\lib\site-packages\loguru\_simple_sinks.py", line 26, in write
    self._stream.write(message)
  File "D:\python3.8\projects\Django\djenv\lib\site-packages\colorama\ansitowin32.py", line 47, in write
    self.__convertor.write(text)
  File "D:\python3.8\projects\Django\djenv\lib\site-packages\colorama\ansitowin32.py", line 170, in write
    self.write_and_convert(text)
  File "D:\python3.8\projects\Django\djenv\lib\site-packages\colorama\ansitowin32.py", line 195, in write_and_convert
    self.write_plain_text(text, cursor, start)
  File "D:\python3.8\projects\Django\djenv\lib\site-packages\colorama\ansitowin32.py", line 203, in write_plain_text
    self.wrapped.write(text[start:end])
  File "D:\python3.8\projects\Django\djenv\lib\site-packages\colorama\ansitowin32.py", line 47, in write
    self.__convertor.write(text)
  File "D:\python3.8\projects\Django\djenv\lib\site-packages\colorama\ansitowin32.py", line 170, in write
    self.write_and_convert(text)
  File "D:\python3.8\projects\Django\djenv\lib\site-packages\colorama\ansitowin32.py", line 198, in write_and_convert
    self.write_plain_text(text, cursor, len(text))
  File "D:\python3.8\projects\Django\djenv\lib\site-packages\colorama\ansitowin32.py", line 204, in write_plain_text
    self.wrapped.flush()
OSError: [WinError 6] 句柄无效。
--- End of logging error ---
--- Logging error in Loguru Handler #0 ---
Record was: {'elapsed': datetime.timedelta(seconds=163, microseconds=345687), 'exception': None, 'extra': {}, 'file': (name='runner.py', path='D:\\python3.8\\projects\\Django\\djenv\\lib\\site-packages\\httprunner\\runner.py'), 'function': 'test_start', 'level': (name='INFO', no=20, icon='ℹ️'), 'line': 460, 'message': 'generate testcase log: D:\\python3.8\\projects\\Django\\autotpsite\\logs\\1a52fd7b-6089-4b78-bd57-b82e0013ff54.run.log', 'module': 'runner', 'name': 'httprunner.runner', 'process': (id=2320, name='MainProcess'), 'thread': (id=10252, name='Thread-1'), 'time': datetime(2022, 10, 10, 0, 8, 59, 685031, tzinfo=datetime.timezone(datetime.timedelta(seconds=28800), '中国标准时间'))}
Traceback (most recent call last):
  File "D:\python3.8\projects\Django\djenv\lib\site-packages\loguru\_handler.py", line 177, in emit
    self._sink.write(str_record)
  File "D:\python3.8\projects\Django\djenv\lib\site-packages\loguru\_simple_sinks.py", line 26, in write
    self._stream.write(message)
  File "D:\python3.8\projects\Django\djenv\lib\site-packages\colorama\ansitowin32.py", line 47, in write
    self.__convertor.write(text)
  File "D:\python3.8\projects\Django\djenv\lib\site-packages\colorama\ansitowin32.py", line 170, in write
    self.write_and_convert(text)
  File "D:\python3.8\projects\Django\djenv\lib\site-packages\colorama\ansitowin32.py", line 195, in write_and_convert
    self.write_plain_text(text, cursor, start)
  File "D:\python3.8\projects\Django\djenv\lib\site-packages\colorama\ansitowin32.py", line 203, in write_plain_text
    self.wrapped.write(text[start:end])
  File "D:\python3.8\projects\Django\djenv\lib\site-packages\colorama\ansitowin32.py", line 47, in write
    self.__convertor.write(text)
  File "D:\python3.8\projects\Django\djenv\lib\site-packages\colorama\ansitowin32.py", line 170, in write
    self.write_and_convert(text)
  File "D:\python3.8\projects\Django\djenv\lib\site-packages\colorama\ansitowin32.py", line 198, in write_and_convert
    self.write_plain_text(text, cursor, len(text))
  File "D:\python3.8\projects\Django\djenv\lib\site-packages\colorama\ansitowin32.py", line 204, in write_plain_text
    self.wrapped.flush()
OSError: [WinError 6] 句柄无效。
--- End of logging error ---
